Workbook

Sheet Phụ lục I Báo giá
A2: BẢNG BÁO GIÁ THIẾT BỊ
B3: Kính gửi: Bệnh viện E
A4: Trên cơ sở yêu cầu báo giá số ngày tháng năm của Bệnh viện E, chúng tôi
A5: Tên công ty:
A6: Địa chỉ:
A7: Mã số thuế:
A8: Báo giá cho các hàng hóa như sau:
A9: 1. Báo giá:
A10: STT trong YCBG | B10: Danh mục thiết bị y tế | C10: Ký, mã, nhãn hiệu, Model | D10: Hãng sản xuất | E10: Năm sản xuất | F10: Xuất xứ | G10: Số lượng | H10: Đơn vị tính | I10: Đơn giá đã bao gồm (Thuế, phí, lệ phí (nếu có) và Chi phí cho các dịch vụ liên quan) | J10: Thành tiền (VNĐ)
B11: =IFERROR(VLOOKUP(A11,'Bảng dữ liệu'!$A$2:$D$30,2,FALSE),"") | G11: =IFERROR(VLOOKUP(A11,'Bảng dữ liệu'!$A$2:$D$30,4,FALSE),"") | H11: =IFERROR(VLOOKUP(A11,'Bảng dữ liệu'!$A$2:$D$30,3,FALSE),"") | J11: =IF(AND(G11>0, I11>0), G11*I11, "")
B12: =IFERROR(VLOOKUP(A12,'Bảng dữ liệu'!$A$2:$D$30,2,FALSE),"") | G12: =IFERROR(VLOOKUP(A12,'Bảng dữ liệu'!$A$2:$D$30,4,FALSE),"") | H12: =IFERROR(VLOOKUP(A12,'Bảng dữ liệu'!$A$2:$D$30,3,FALSE),"") | J12: =IF(AND(G12>0, I12>0), G12*I12, "")
B13: =IFERROR(VLOOKUP(A13,'Bảng dữ liệu'!$A$2:$D$30,2,FALSE),"") | G13: =IFERROR(VLOOKUP(A13,'Bảng dữ liệu'!$A$2:$D$30,4,FALSE),"") | H13: =IFERROR(VLOOKUP(A13,'Bảng dữ liệu'!$A$2:$D$30,3,FALSE),"") | J13: =IF(AND(G13>0, I13>0), G13*I13, "")
B14: =IFERROR(VLOOKUP(A14,'Bảng dữ liệu'!$A$2:$D$30,2,FALSE),"") | G14: =IFERROR(VLOOKUP(A14,'Bảng dữ liệu'!$A$2:$D$30,4,FALSE),"") | H14: =IFERROR(VLOOKUP(A14,'Bảng dữ liệu'!$A$2:$D$30,3,FALSE),"") | J14: =IF(AND(G14>0, I14>0), G14*I14, "")
B15: =IFERROR(VLOOKUP(A15,'Bảng dữ liệu'!$A$2:$D$30,2,FALSE),"") | G15: =IFERROR(VLOOKUP(A15,'Bảng dữ liệu'!$A$2:$D$30,4,FALSE),"") | H15: =IFERROR(VLOOKUP(A15,'Bảng dữ liệu'!$A$2:$D$30,3,FALSE),"") | J15: =IF(AND(G15>0, I15>0), G15*I15, "")
B16: =IFERROR(VLOOKUP(A16,'Bảng dữ liệu'!$A$2:$D$30,2,FALSE),"") | G16: =IFERROR(VLOOKUP(A16,'Bảng dữ liệu'!$A$2:$D$30,4,FALSE),"") | H16: =IFERROR(VLOOKUP(A16,'Bảng dữ liệu'!$A$2:$D$30,3,FALSE),"") | J16: =IF(AND(G16>0, I16>0), G16*I16, "")
B17: =IFERROR(VLOOKUP(A17,'Bảng dữ liệu'!$A$2:$D$30,2,FALSE),"") | G17: =IFERROR(VLOOKUP(A17,'Bảng dữ liệu'!$A$2:$D$30,4,FALSE),"") | H17: =IFERROR(VLOOKUP(A17,'Bảng dữ liệu'!$A$2:$D$30,3,FALSE),"") | J17: =IF(AND(G17>0, I17>0), G17*I17, "")
A18: 2. Báo giá này có hiệu lực trong vòng: 180 ngày kể từ ngày tháng năm ;
A19: 3. Chúng tôi cam kết:
A20: - Không đang trong quá trình thực hiện thủ tục giải thể hoặc bị thu hồi Giấy chứng nhận đăng ký doanh nghiệp hoặc Giấy chứng nhận đăng ký hộ kinh doanh hoặc các tài liệu tương đương khác; không thuộc trường hợp mất khả năng thanh toán theo quy định của pháp luật về doanh nghiệp
A21: - Cung cấp thông tin về giá của hàng hóa, dịch vụ phù hợp với khả năng cung cấp của mình và phải bảo đảm việc cung cấp báo giá không vi phạm quy định của pháp luật về cạnh tranh, bán phá giá hoặc nâng khống giá
A22: - Những thông tin nêu trong báo giá là trung thực.
A23: 4. Thông tin liên hệ của đơn vị báo giá:
G24: Hà Nội, ngày tháng năm
G25: ĐẠI DIỆN ĐƠN VỊ BÁO GIÁ

Sheet Bảng dữ liệu
A2: STT | B2: Tên hàng hóa | C2: Đơn vị tính | D2: Số lượng
A3: I | B3: Thiết bị Hồi sức - Cấp cứu
A4: TB 01 | B4: Bơm tiêm điện | C4: Cái | D4: 64
A5: TB 02 | B5: Bơm tiêm điện (Có kết nối từ xa, chuyên dụng cho Phòng phẫu thuật) | C5: Cái | D5: 18
A6: TB 03 | B6: Bơm truyền dịch | C6: Cái | D6: 57
A7: TB 04 | B7: Máy điện tim ≥ 12 kênh | C7: Cái | D7: 14
A8: TB 05 | B8: Máy vỗ rung lồng ngực cao tần | C8: Cái | D8: 10
A9: II | B9: Thiết bị Chẩn đoán hình ảnh
A10: TB 06 | B10: Máy X-quang di động kỹ thuật số DR | C10: Cái | D10: 1
A11: TB 07 | B11: Máy bơm tiêm điện 2 nòng (Dùng cho phòng chụp CLVT) | C11: Cái | D11: 1
A12: TB 08 | B12: Hệ thống máy đốt sóng cao tần (RFA) | C12: Hệ thống | D12: 1
A13: III | B13: Hệ thống Nội soi thăm dò chức năng
A14: TB 09 | B14: Hệ thống nội soi tiêu hóa (Kèm Hệ thống trí tuệ nhân tạo trong nội soi và mô hình giả lập nội soi đại tràng) | C14: Hệ thống | D14: 1
A15: TB 10 | B15: Hệ thống nội soi tiêu hóa (Kèm Hệ thống trí tuệ nhân tạo trong nội soi) | C15: Hệ thống | D15: 1
A16: IV | B16: Thiết bị thần kinh và sức khỏe tâm thần
A17: TB 11 | B17: Máy kích thích điện một chiều xuyên sọ | C17: Cái | D17: 3
A18: TB 12 | B18: Máy điện não vi tính | C18: Cái | D18: 1
A19: TB 13 | B19: Máy lưu huyết não | C19: Cái | D19: 1
A20: TB 14 | B20: Máy đa ký giấc ngủ | C20: Cái | D20: 2
A21: V | B21: Thiết bị hô hấp
A22: TB 15 | B22: Hệ thống thăm dò chức năng hô hấp bằng phương pháp dao động xung ký | C22: Hệ thống | D22: 1
A23: VI | B23: Thiết bị chuyên khoa Răng Hàm Mặt
A24: TB 16 | B24: Máy chụp CT Conebeam | C24: Cái | D24: 1
A25: TB 17 | B25: Hệ thống khoan cắt xương dùng trong phẫu thuật hàm mặt | C25: Hệ thống | D25: 1
A26: VII | B26: Thiết bị chuyên khoa Mắt
A27: TB 18 | B27: Máy đo thị trường | C27: Cái | D27: 1
A28: TB 19 | B28: Máy chụp cắt lớp võng mạc OCT | C28: Cái | D28: 1
A29: VIII | B29: Thiết bị chuyên khoa Thẩm mỹ và phẫu thuật tạo hình
A30: TB 20 | B30: Máy bào da | C30: Cái | D30: 1

Sheet Phụ lục II Báo giá bảo hành
B2: CÔNG TY CỔ PHẦN THIẾT BỊ VÀ DỊCH VỤ Y TẾ VIỆT NAM
B3: Địa chỉ: Số 61, thôn 6, xã Sơn Đồng, TP. Hà Nội, Việt Nam
B4: Hà Nội: Số A14-BT4 Bùi Xuân Phái, Phường Từ Liêm, Hà Nội
B5: HCM: Số 371 Nguyễn Xí, phường Bình Lợi Trung, TP.Hồ Chí Minh
B6: Email: vnmedica.phongsale@gmail.com
A8: BẢNG BÁO GIÁ DỊCH VỤ BẢO HÀNH, BẢO TRÌ THIẾT BỊ SAU THỜI GIAN BẢO HÀNH TIÊU CHUẨN
B9: Kính gửi: Bệnh viện E
A10: Trên cơ sở yêu cầu báo giá số RQ2600027903 ngày 15 tháng 7 năm 2026 của Bệnh viện E, chúng tôi- Công ty Cổ phần Thiết bị và Dịch vụ Y tế Việt Nam có địa chỉ tại Số nhà 61 thôn 6, xã Sơn Đồng, TP. Hà Nội, Mã số thuế: 0108936926 Báo giá cho các dịch vụ như sau:
A11: 1. Báo giá:
A12: STT | B12: Danh mục dịch vụ | C12: Số lượng | D12: Đơn vị tính | E12: Đơn giá đã bao gồm (Thuế, phí, lệ phí (nếu có) và Chi phí cho các dịch vụ liên quan) | F12: Thành tiền (VNĐ) | G12: Ghi chú
A13: 1 | B13: Dịch vụ bảo hành, bảo trì Máy điện tim ≥ 12 kênh Model: BeneHeart R700 Hãng sản xuất: Shenzhen Mindray Bio-Medical Electronics Co.,Ltd. Xuất xứ: Trung Quốc | C13: 14 Cái | D13: Gói 12 tháng | E13: 10000000 | F13: =E13*14 -> 140000000
A14: 2 | B14: Dịch vụ bảo hành, bảo trì Hệ thống thăm dò chức năng hô hấp bằng phương pháp dao động xung ký Model: Vyntus IOS Hãng sản xuất: Jaeger Medical GmbH Xuất xứ: Đức | C14: 01 Hệ thống | D14: Gói 12 tháng | E14: 80000000 | F14: 80000000
A15: 2. Báo giá này có hiệu lực trong vòng: 180 ngày kể từ ngày 29 tháng 7 năm 2026;
A16: 3. Chúng tôi cam kết:
A17: - Không đang trong quá trình thực hiện thủ tục giải thể hoặc bị thu hồi Giấy chứng nhận đăng ký doanh nghiệp hoặc Giấy chứng nhận đăng ký hộ kinh doanh hoặc các tài liệu tương đương khác; không thuộc trường hợp mất khả năng thanh toán theo quy định của pháp luật về doanh nghiệp
A18: - Cung cấp thông tin về giá của hàng hóa, dịch vụ phù hợp với khả năng cung cấp của mình và phải bảo đảm việc cung cấp báo giá không vi phạm quy định của pháp luật về cạnh tranh, bán phá giá hoặc nâng khống giá
A19: - Những thông tin nêu trong báo giá là trung thực.
A20: 4. Thông tin liên hệ của đơn vị báo giá: Hotline: 0877005500/ Mr Hải: 0963961651
E21: Hà Nội, ngày 27 tháng 7 năm 2026
E22: ĐẠI DIỆN ĐƠN VỊ BÁO GIÁ

Sheet Phụ lục III Bảng ĐUKT
A1: BẢNG ĐÁP ỨNG KỸ THUẬT HÀNG HÓA CHÀO GIÁ
A3: Yêu cầu báo giá | E3: Thông số kỹ thuật hàng hóa chào giá
A4: STT | B4: STT trong yêu cầu báo giá | C4: Tên danh mục trong yêu cầu báo giá | D4: Tính năng kỹ thuật trong yêu cầu báo giá | E4: Tên thương mại hàng hóa | F4: Thông số đáp ứng (1) | G4: Thông số không đáp ứng (2) | H4: Thông số kỹ thuật tương đương hoặc tốt hơn yêu cầu mời chào giá (3) | I4: Thuyết minh cho trường hợp (2), (3) | J4: Tài liệu tham chiếu
A5: 1 | B5: TB04 | C5: Máy điện tim ≥ 12 kênh | E5: Máy điện tim | F5: Model: BeneHeart R700 Hãng sản xuất: Shenzhen Mindray Bio-Medical Electronics Co.,Ltd. Xuất xứ: Trung Quốc
D6: I. Yêu cầu chung | F6: I. Đáp ứng yêu cầu chung
D7: Máy chính được sản xuất từ năm 2026 trở đi, mới 100%. | F7: Máy chính được sản xuất từ năm 2026 trở đi, mới 100%. | J7: Cam kết cung cấp
D8: Nhà sản xuất máy chính đạt chứng nhận: ISO 13485 | F8: Nhà sản xuất máy chính đạt chứng nhận: ISO 13485 | J8: Cam kết cung cấp
D9: Nguồn điện sử dụng: phù hợp với tiêu chuẩn điện áp tại Việt Nam | F9: Nguồn điện sử dụng: phù hợp với tiêu chuẩn điện áp tại Việt Nam 100 – 240V, 50/60Hz | J9: Cam kết cung cấp Datasheet trang 2: Power + AC power Input voltage: 100 to 240 VAC AC frequency: 50/60 Hz
D10: Nhiệt độ hoạt động tối đa ≥ 40°C | F10: Nhiệt độ hoạt động tối đa 40°C | J10: Operator manual trang A-1 mục A.1.2 Environmental Specifications Operating condition Temperature 5ºC to 40ºC
D11: Độ ẩm hoạt động tối đa ≥ 80% | F11: Độ ẩm hoạt động tối đa 95% | J11: Operator manual trang A-1 mục A.1.2 Environmental Specifications Operating condition Relative humidity 15% to 95%, non-condensing
D12: II. Yêu cầu cấu hình (cho 01 thiết bị): | F12: II. Đáp ứng yêu cầu cấu hình (cho 01 thiết bị):
D13: Máy điện tim ≥ 12 kênh kèm phụ kiện theo tiêu chuẩn | F13: Máy điện tim 12 kênh kèm phụ kiện theo tiêu chuẩn
D14: Máy chính: 01 cái | F14: Máy chính: 01 cái | J14: Cam kết cung cấp
D15: Dây nối điện tim: 01 cái | F15: Dây nối điện tim: 01 cái | J15: Cam kết cung cấp
D16: Dây nguồn: 01 cái | F16: Dây nguồn: 01 cái | J16: Cam kết cung cấp
D17: Điện cực trước ngực: 06 quả | F17: Điện cực trước ngực: 06 quả | J17: Cam kết cung cấp
D18: Điện cực chi: 04 cái | F18: Điện cực chi: 04 cái | J18: Cam kết cung cấp
D19: Ắc quy: 01 cái | F19: Ắc quy: 01 cái | J19: Cam kết cung cấp
D20: Giấy in: 01 tập | F20: Giấy in: 01 tập | J20: Cam kết cung cấp
D21: Xe đẩy : 01 cái | F21: Xe đẩy: 01 cái (Mua tại Việt Nam) | J21: Cam kết cung cấp
D22: Tài liệu hướng dẫn sử dụng Tiếng Việt và Tiếng Anh: 01 bộ | F22: Tài liệu hướng dẫn sử dụng Tiếng Việt và Tiếng Anh: 01 bộ | J22: Cam kết cung cấp
D23: III. Yêu cầu kỹ thuật | F23: III. Đáp ứng yêu cầu kỹ thuật
D24: A. Tính năng chung | F24: A. Tính năng chung
D25: 1. Hiển thị: | F25: 1. Hiển thị:
D26: Kiểu hiển thị: Màn hình màu, kích thước ≥ 8 inches | F26: Kiểu hiển thị: Màn hình cảm ứng điện dung màu, kích thước 12.1 inches | J26: Datasheet trang 2: Display Display type Capacitive, multi-point color touchscreen Display size 12.1 inches
D27: Độ phân giải màn hình: ≥ 800 x 480 dots/ pixel | F27: Độ phân giải màn hình: 1280 x 800 pixel | J27: Datasheet trang 2: Display Display resolution 1280×800 pixels
D28: Dạng sóng điện tim: ít nhất 12 đạo trình; | F28: Dạng sóng điện tim: 12 đạo trình; | J28: Operator manual trang 3-5 mục 3.7 Main Screen Display + hình ảnh
D29: 2. Thu nhận tín hiệu | F29: 2. Thu nhận tín hiệu
D30: Ghi đạo trình tối đa: ≥ 12 đạo trình | F30: Ghi đạo trình tối đa: 12 đạo trình | J30: Operator manual trang A-4 mục A.7 Measurement Specifications Lead type 12-lead
D31: Tần số đáp ứng: Từ ≤ 0.05 Hz đến ≥ 150 Hz | F31: Tần số đáp ứng: Từ 0.01 Hz đến 500 Hz | J31: Datasheet trang 1: Measurement Specifications Frequency response 0.01~500Hz
D32: Nhiễu trong: ≤ 20μVp-v (Vp-p) | F32: Nhiễu trong: ≤ 12.5 μV (p-p) | J32: Datasheet trang 1: Measurement Specifications Noise level ≤12.5 μV (p-p)
D33: 3. Xử lý tín hiệu | F33: 3. Xử lý tín hiệu
D34: Bộ lọc nhiễu xoay chiều: 50/60 Hz | F34: Bộ lọc nhiễu xoay chiều: 50/60 Hz | J34: Datasheet trang 1: Measurement Specifications Notch filter 50 Hz, 60 Hz, OFF
D35: Có bộ lọc chống trôi | F35: Có bộ lọc chống trôi | J35: Datasheet trang 1: Measurement Specifications Baseline filter 0.01Hz, 0.05 Hz, 0.56 Hz
D36: Độ nhạy: tối thiểu 3 mức lựa chọn | F36: Độ nhạy: 5 mức lựa chọn | J36: Datasheet trang 1: Measurement Specifications Display sensitivity Auto, 1.25 mm/mV, 2.5 mm/mV , 5 mm/mV, 10 mm/mV, 20 mm/mV , 10/5 mm/mV, 20/10 mm/mV, (± 5%)
D37: 4. Ghi | F37: 4. Ghi
D38: Số kênh: ≥ 12 kênh | F38: Số kênh: 12 kênh | J38: Operator manual trang 6-8 mục 6.8 Printing Reports The equipment can print out the following reports: ■ Standard 12-lead ECG report
D39: Tốc độ giấy: Có lựa chọn tốc độ tối thiểu ≥ 2 mức | F39: Tốc độ giấy: Có lựa chọn tốc độ 4 mức | J39: Datasheet trang 2: Recorder Paper speed 5 mm/s, 12.5 mm/s, 25 mm/s, 50 mm/s.
D40: Giấy ghi: độ rộng giấy ≥ 210 mm | F40: Giấy ghi: độ rộng giấy 210 mm | J40: Datasheet trang 2: Recorder Paper type Thermal Z-fold A4 paper (210 mm x 295 mm)
D41: Có chức năng ghi mở rộng | F41: Có chức năng ghi mở rộng | J41: Operator manual trang 6-8 mục 6.8 Printing Reports The equipment can print out the following reports: ■ Additional lead report ■ Manual report (for recorder only) ■ Rhythm report ■ Medication test report ■ Frozen waveform report ■ Review report ■ Re-analysis repor
...

Sheet Phụ lục IV Kê khai TSKT
A1: CẤU HÌNH VÀ THÔNG SỐ KỸ THUẬT CHI TIẾT CỦA HÀNG HÓA
A2: STT | B2: Thông tin
B143: Đại diện hợp pháp của Đơn vị chào giá
